Traceback (most recent call last):
  File "/home/runner/CollegeCounselorAI/agents/base.py", line 118, in get_response
    messages = self._build_messages(message, context)
               ^^^^^^^^^^^^^^^^^^^^^^^^^^^^^^^^^^^^^^
  File "/home/runner/CollegeCounselorAI/agents/base.py", line 135, in _build_messages
    "content": f"Context: {json.dumps(context)}"
                           ^^^^^^^^^^^^^^^^^^^
  File "/nix/store/clx0mcir7qw8zk36zbr4jra789g3knf6-python3-3.11.10/lib/python3.11/json/__init__.py", line 231, in dumps
    return _default_encoder.encode(obj)
           ^^^^^^^^^^^^^^^^^^^^^^^^^^^^
  File "/nix/store/clx0mcir7qw8zk36zbr4jra789g3knf6-python3-3.11.10/lib/python3.11/json/encoder.py", line 200, in encode
    chunks = self.iterencode(o, _one_shot=True)
             ^^^^^^^^^^^^^^^^^^^^^^^^^^^^^^^^^^
  File "/nix/store/clx0mcir7qw8zk36zbr4jra789g3knf6-python3-3.11.10/lib/python3.11/json/encoder.py", line 258, in iterencode
    return _iterencode(o, 0)
           ^^^^^^^^^^^^^^^^^
  File "/nix/store/clx0mcir7qw8zk36zbr4jra789g3knf6-python3-3.11.10/lib/python3.11/json/encoder.py", line 180, in default
    raise TypeError(f'Object of type {o.__class__.__name__} '
TypeError: Object of type datetime is not JSON serializable

During handling of the above exception, another exception occurred:

Traceback (most recent call last):
  File "/home/runner/CollegeCounselorAI/agents/orchestrator.py", line 89, in process_message
    response = self.agents["counselor"].get_response(message, context)
               ^^^^^^^^^^^^^^^^^^^^^^^^^^^^^^^^^^^^^^^^^^^^^^^^^^^^^^^
  File "/home/runner/CollegeCounselorAI/agents/base.py", line 125, in get_response
    raise AgentError(f"Failed to generate response in {self.__class__.__name__}")
agents.base.AgentError: Failed to generate response in PrimaryCounselorAgent

During handling of the above exception, another exception occurred:

Traceback (most recent call last):
  File "/home/runner/CollegeCounselorAI/agents/orchestrator.py", line 96, in process_message
    raise AgentError("Unable to generate response. Please try again.")
agents.base.AgentError: Unable to generate response. Please try again.

During handling of the above exception, another exception occurred:

Traceback (most recent call last):
  File "/home/runner/CollegeCounselorAI/components/chat.py", line 113, in render_chat
    response = loop.run_until_complete(
               ^^^^^^^^^^^^^^^^^^^^^^^^
  File "/nix/store/clx0mcir7qw8zk36zbr4jra789g3knf6-python3-3.11.10/lib/python3.11/asyncio/base_events.py", line 654, in run_until_complete
    return future.result()
           ^^^^^^^^^^^^^^^
  File "/home/runner/CollegeCounselorAI/agents/orchestrator.py", line 100, in process_message
    raise AgentError(str(e))
agents.base.AgentError: Unable to generate response. Please try again.