Traceback (most recent call last):
  File "/home/runner/CollegeCounselorAI/agents/primary_counselor.py", line 127, in _build_messages
    "content": self.config.get('system_prompt_template', '')
               ^^^^^^^^^^^^^^^
  File "/home/runner/CollegeCounselorAI/.pythonlibs/lib/python3.11/site-packages/pydantic/main.py", line 892, in __getattr__
    raise AttributeError(f'{type(self).__name__!r} object has no attribute {item!r}')
AttributeError: 'ModelConfig' object has no attribute 'get'

During handling of the above exception, another exception occurred:

Traceback (most recent call last):
  File "/home/runner/CollegeCounselorAI/agents/primary_counselor.py", line 204, in get_response
    messages = self._build_messages(message, context)
               ^^^^^^^^^^^^^^^^^^^^^^^^^^^^^^^^^^^^^^
  File "/home/runner/CollegeCounselorAI/agents/primary_counselor.py", line 150, in _build_messages
    raise AgentError("Failed to build messages")
agents.base.AgentError: Failed to build messages

During handling of the above exception, another exception occurred:

Traceback (most recent call last):
  File "/home/runner/CollegeCounselorAI/agents/orchestrator.py", line 89, in process_message
    response = self.agents["counselor"].get_response(message, context)
               ^^^^^^^^^^^^^^^^^^^^^^^^^^^^^^^^^^^^^^^^^^^^^^^^^^^^^^^
  File "/home/runner/CollegeCounselorAI/agents/primary_counselor.py", line 216, in get_response
    raise AgentError(f"Failed to generate response in {self.__class__.__name__}")
agents.base.AgentError: Failed to generate response in PrimaryCounselorAgent

During handling of the above exception, another exception occurred:

Traceback (most recent call last):
  File "/home/runner/CollegeCounselorAI/agents/orchestrator.py", line 96, in process_message
    raise AgentError("Unable to generate response. Please try again.")
agents.base.AgentError: Unable to generate response. Please try again.

During handling of the above exception, another exception occurred:

Traceback (most recent call last):
  File "/home/runner/CollegeCounselorAI/components/chat.py", line 137, in render_chat
    response = loop.run_until_complete(
               ^^^^^^^^^^^^^^^^^^^^^^^^
  File "/nix/store/clx0mcir7qw8zk36zbr4jra789g3knf6-python3-3.11.10/lib/python3.11/asyncio/base_events.py", line 654, in run_until_complete
    return future.result()
           ^^^^^^^^^^^^^^^
  File "/home/runner/CollegeCounselorAI/agents/orchestrator.py", line 100, in process_message
    raise AgentError(str(e))
agents.base.AgentError: Unable to generate response. Please try again.